<?xml version="1.0" ?>
<robot name="UCV_robot_urdf" xmlns:xacro="http://www.ros.org/wiki/xacro">

<xacro:include filename="$(find UCV_robot_urdf_description)/urdf/materials.xacro" />
<xacro:include filename="$(find UCV_robot_urdf_description)/urdf/UCV_robot_urdf.trans" />
<xacro:include filename="$(find UCV_robot_urdf_description)/urdf/UCV_robot_urdf.gazebo" />
<link name="base_link">
  <inertial>
    <origin xyz="0.0005684663800967518 1.6861442325013395e-06 0.051628550037310636" rpy="0 0 0"/>
    <mass value="5.453505423835813"/>
    <inertia ixx="0.066842" iyy="0.046567" izz="0.113336" ixy="-0.0" iyz="-0.0" ixz="8.3e-05"/>
  </inertial>
  <visual>
    <origin xyz="0 0 0" rpy="0 0 0"/>
    <geometry>
      <mesh filename="package://UCV_robot_urdf_description/meshes/base_link.stl" scale="0.001 0.001 0.001"/>
    </geometry>
    <material name="silver"/>
  </visual>
  <collision>
    <origin xyz="0 0 0" rpy="0 0 0"/>
    <geometry>
      <mesh filename="package://UCV_robot_urdf_description/meshes/base_link.stl" scale="0.001 0.001 0.001"/>
    </geometry>
  </collision>
</link>

<link name="Servo_v1_1">
  <inertial>
    <origin xyz="0.00775150326042473 0.005214358475538666 -0.014250000000005522" rpy="0 0 0"/>
    <mass value="0.3417439075057314"/>
    <inertia ixx="5.5e-05" iyy="8.4e-05" izz="9.5e-05" ixy="-1e-06" iyz="0.0" ixz="0.0"/>
  </inertial>
  <visual>
    <origin xyz="0.092 0.186 -0.04725" rpy="0 0 0"/>
    <geometry>
      <mesh filename="package://UCV_robot_urdf_description/meshes/Servo_v1_1.stl" scale="0.001 0.001 0.001"/>
    </geometry>
    <material name="silver"/>
  </visual>
  <collision>
    <origin xyz="0.092 0.186 -0.04725" rpy="0 0 0"/>
    <geometry>
      <mesh filename="package://UCV_robot_urdf_description/meshes/Servo_v1_1.stl" scale="0.001 0.001 0.001"/>
    </geometry>
  </collision>
</link>

<link name="Servo_v1__1__1">
  <inertial>
    <origin xyz="0.00775150326042473 -0.005214358475538083 -0.014250000000034471" rpy="0 0 0"/>
    <mass value="0.3417439075057314"/>
    <inertia ixx="5.5e-05" iyy="8.4e-05" izz="9.5e-05" ixy="1e-06" iyz="0.0" ixz="-0.0"/>
  </inertial>
  <visual>
    <origin xyz="0.092 -0.186 -0.04725" rpy="0 0 0"/>
    <geometry>
      <mesh filename="package://UCV_robot_urdf_description/meshes/Servo_v1__1__1.stl" scale="0.001 0.001 0.001"/>
    </geometry>
    <material name="silver"/>
  </visual>
  <collision>
    <origin xyz="0.092 -0.186 -0.04725" rpy="0 0 0"/>
    <geometry>
      <mesh filename="package://UCV_robot_urdf_description/meshes/Servo_v1__1__1.stl" scale="0.001 0.001 0.001"/>
    </geometry>
  </collision>
</link>

<link name="Wheel_v2_1">
  <inertial>
    <origin xyz="-8.619866748993399e-07 0.007884164770174618 -1.432599677102242e-06" rpy="0 0 0"/>
    <mass value="0.029886631406815363"/>
    <inertia ixx="1.1e-05" iyy="2.1e-05" izz="1.1e-05" ixy="-0.0" iyz="0.0" ixz="0.0"/>
  </inertial>
  <visual>
    <origin xyz="0.096 -0.199 -0.033" rpy="0 0 0"/>
    <geometry>
      <mesh filename="package://UCV_robot_urdf_description/meshes/Wheel_v2_1.stl" scale="0.001 0.001 0.001"/>
    </geometry>
    <material name="silver"/>
  </visual>
  <collision>
    <origin xyz="0.096 -0.199 -0.033" rpy="0 0 0"/>
    <geometry>
      <mesh filename="package://UCV_robot_urdf_description/meshes/Wheel_v2_1.stl" scale="0.001 0.001 0.001"/>
    </geometry>
  </collision>
</link>

<link name="Wheel_v2__1__1">
  <inertial>
    <origin xyz="-9.5793546260603e-07 -0.007884164770174007 1.3636102257560956e-06" rpy="0 0 0"/>
    <mass value="0.029886631406815363"/>
    <inertia ixx="1.1e-05" iyy="2.1e-05" izz="1.1e-05" ixy="0.0" iyz="0.0" ixz="-0.0"/>
  </inertial>
  <visual>
    <origin xyz="0.096 0.199 -0.033" rpy="0 0 0"/>
    <geometry>
      <mesh filename="package://UCV_robot_urdf_description/meshes/Wheel_v2__1__1.stl" scale="0.001 0.001 0.001"/>
    </geometry>
    <material name="silver"/>
  </visual>
  <collision>
    <origin xyz="0.096 0.199 -0.033" rpy="0 0 0"/>
    <geometry>
      <mesh filename="package://UCV_robot_urdf_description/meshes/Wheel_v2__1__1.stl" scale="0.001 0.001 0.001"/>
    </geometry>
  </collision>
</link>

<link name="Layer_v2_1">
  <inertial>
    <origin xyz="-0.06343153450777987 1.6861442365080336e-06 -0.027871449962689365" rpy="0 0 0"/>
    <mass value="5.453505423835813"/>
    <inertia ixx="0.066842" iyy="0.046567" izz="0.113336" ixy="-0.0" iyz="-0.0" ixz="8.3e-05"/>
  </inertial>
  <visual>
    <origin xyz="-0.064 -0.0 -0.1115" rpy="0 0 0"/>
    <geometry>
      <mesh filename="package://UCV_robot_urdf_description/meshes/Layer_v2_1.stl" scale="0.001 0.001 0.001"/>
    </geometry>
    <material name="silver"/>
  </visual>
  <collision>
    <origin xyz="-0.064 -0.0 -0.1115" rpy="0 0 0"/>
    <geometry>
      <mesh filename="package://UCV_robot_urdf_description/meshes/Layer_v2_1.stl" scale="0.001 0.001 0.001"/>
    </geometry>
  </collision>
</link>

<link name="batteries_v2_1">
  <inertial>
    <origin xyz="0.15099999911209713 -5.683892408333141e-15 0.04703104967731736" rpy="0 0 0"/>
    <mass value="9.23198"/>
    <inertia ixx="0.08807" iyy="0.077039" izz="0.151495" ixy="0.0" iyz="-0.0" ixz="-0.0"/>
  </inertial>
  <visual>
    <origin xyz="0.157 0.0 -0.08825" rpy="0 0 0"/>
    <geometry>
      <mesh filename="package://UCV_robot_urdf_description/meshes/batteries_v2_1.stl" scale="0.001 0.001 0.001"/>
    </geometry>
    <material name="silver"/>
  </visual>
  <collision>
    <origin xyz="0.157 0.0 -0.08825" rpy="0 0 0"/>
    <geometry>
      <mesh filename="package://UCV_robot_urdf_description/meshes/batteries_v2_1.stl" scale="0.001 0.001 0.001"/>
    </geometry>
  </collision>
</link>

<link name="Layer_v2__1__1">
  <inertial>
    <origin xyz="-0.06343153539565648 1.6861442405244987e-06 0.020128550037310622" rpy="0 0 0"/>
    <mass value="5.453505423835813"/>
    <inertia ixx="0.066842" iyy="0.046567" izz="0.113336" ixy="-0.0" iyz="-0.0" ixz="8.3e-05"/>
  </inertial>
  <visual>
    <origin xyz="-0.064 -0.0 -0.1755" rpy="0 0 0"/>
    <geometry>
      <mesh filename="package://UCV_robot_urdf_description/meshes/Layer_v2__1__1.stl" scale="0.001 0.001 0.001"/>
    </geometry>
    <material name="silver"/>
  </visual>
  <collision>
    <origin xyz="-0.064 -0.0 -0.1755" rpy="0 0 0"/>
    <geometry>
      <mesh filename="package://UCV_robot_urdf_description/meshes/Layer_v2__1__1.stl" scale="0.001 0.001 0.001"/>
    </geometry>
  </collision>
</link>

<link name="RealSense_D435_v1_1">
  <inertial>
    <origin xyz="-0.0009785680144069886 -1.1079651961295413e-05 0.012138125786793935" rpy="0 0 0"/>
    <mass value="0.10791100846631752"/>
    <inertia ixx="7.1e-05" iyy="1e-05" izz="7.2e-05" ixy="-0.0" iyz="0.0" ixz="-0.0"/>
  </inertial>
  <visual>
    <origin xyz="0.142 0.0 -0.20025" rpy="0 0 0"/>
    <geometry>
      <mesh filename="package://UCV_robot_urdf_description/meshes/RealSense_D435_v1_1.stl" scale="0.001 0.001 0.001"/>
    </geometry>
    <material name="silver"/>
  </visual>
  <collision>
    <origin xyz="0.142 0.0 -0.20025" rpy="0 0 0"/>
    <geometry>
      <mesh filename="package://UCV_robot_urdf_description/meshes/RealSense_D435_v1_1.stl" scale="0.001 0.001 0.001"/>
    </geometry>
  </collision>
</link>

<link name="D435_holder_1">
  <inertial>
    <origin xyz="0.002977569990864376 0.022500033233597637 -0.003563974203140252" rpy="0 0 0"/>
    <mass value="0.042723847582990575"/>
    <inertia ixx="1.2e-05" iyy="1e-06" izz="1.1e-05" ixy="-0.0" iyz="-0.0" ixz="0.0"/>
  </inertial>
  <visual>
    <origin xyz="0.131423 0.0225 -0.212524" rpy="0 0 0"/>
    <geometry>
      <mesh filename="package://UCV_robot_urdf_description/meshes/D435_holder_1.stl" scale="0.001 0.001 0.001"/>
    </geometry>
    <material name="silver"/>
  </visual>
  <collision>
    <origin xyz="0.131423 0.0225 -0.212524" rpy="0 0 0"/>
    <geometry>
      <mesh filename="package://UCV_robot_urdf_description/meshes/D435_holder_1.stl" scale="0.001 0.001 0.001"/>
    </geometry>
  </collision>
</link>

<link name="LDS_01_v1_1">
  <inertial>
    <origin xyz="0.04110289696669861 1.2840387008725982e-05 0.0006058195721056203" rpy="0 0 0"/>
    <mass value="0.05487799206614008"/>
    <inertia ixx="1.8e-05" iyy="3.6e-05" izz="4.5e-05" ixy="0.0" iyz="-0.0" ixz="5e-06"/>
  </inertial>
  <visual>
    <origin xyz="0.125423 -0.0 -0.217524" rpy="0 0 0"/>
    <geometry>
      <mesh filename="package://UCV_robot_urdf_description/meshes/LDS_01_v1_1.stl" scale="0.001 0.001 0.001"/>
    </geometry>
    <material name="silver"/>
  </visual>
  <collision>
    <origin xyz="0.125423 -0.0 -0.217524" rpy="0 0 0"/>
    <geometry>
      <mesh filename="package://UCV_robot_urdf_description/meshes/LDS_01_v1_1.stl" scale="0.001 0.001 0.001"/>
    </geometry>
  </collision>
</link>

<joint name="Rigid 1" type="fixed">
  <origin xyz="-0.092 -0.186 0.04725" rpy="0 0 0"/>
  <parent link="base_link"/>
  <child link="Servo_v1_1"/>
</joint>

<joint name="Rigid 2" type="fixed">
  <origin xyz="-0.092 0.186 0.04725" rpy="0 0 0"/>
  <parent link="base_link"/>
  <child link="Servo_v1__1__1"/>
</joint>

<joint name="Revolute 3" type="continuous">
  <origin xyz="-0.004 0.013 -0.01425" rpy="0 0 0"/>
  <parent link="Servo_v1__1__1"/>
  <child link="Wheel_v2_1"/>
  <axis xyz="-0.0 -1.0 -0.0"/>
</joint>

<joint name="Revolute 4" type="continuous">
  <origin xyz="-0.004 -0.013 -0.01425" rpy="0 0 0"/>
  <parent link="Servo_v1_1"/>
  <child link="Wheel_v2__1__1"/>
  <axis xyz="0.0 1.0 0.0"/>
</joint>

<joint name="Rigid 5" type="fixed">
  <origin xyz="0.064 0.0 0.1115" rpy="0 0 0"/>
  <parent link="base_link"/>
  <child link="Layer_v2_1"/>
</joint>

<joint name="Rigid 6" type="fixed">
  <origin xyz="-0.221 -0.0 -0.02325" rpy="0 0 0"/>
  <parent link="Layer_v2_1"/>
  <child link="batteries_v2_1"/>
</joint>

<joint name="Rigid 7" type="fixed">
  <origin xyz="0.0 0.0 0.064" rpy="0 0 0"/>
  <parent link="Layer_v2_1"/>
  <child link="Layer_v2__1__1"/>
</joint>

<joint name="Rigid 8" type="fixed">
  <origin xyz="-0.206 -0.0 0.02475" rpy="0 0 0"/>
  <parent link="Layer_v2__1__1"/>
  <child link="RealSense_D435_v1_1"/>
</joint>

<joint name="Rigid 9" type="fixed">
  <origin xyz="0.010577 -0.0225 0.012274" rpy="0 0 0"/>
  <parent link="RealSense_D435_v1_1"/>
  <child link="D435_holder_1"/>
</joint>

<joint name="Rigid 10" type="fixed">
  <origin xyz="0.006 0.0225 0.005" rpy="0 0 0"/>
  <parent link="D435_holder_1"/>
  <child link="LDS_01_v1_1"/>
</joint>

</robot>
