<?xml version="1.0" ?>
<robot name="uvc_robot" xmlns:xacro="http://www.ros.org/wiki/xacro">

<xacro:include filename="$(find uvc_robot_description)/urdf/materials.xacro" />
<xacro:include filename="$(find uvc_robot_description)/urdf/uvc_robot.trans" />
<xacro:include filename="$(find uvc_robot_description)/urdf/uvc_robot.gazebo" />
<link name="base_link">
  <inertial>
    <origin xyz="0.003044357800664088 -5.813280535031303e-08 0.049763649412406935" rpy="0 0 0"/>
    <mass value="6.650135283544515"/>
    <inertia ixx="0.083929" iyy="0.07109" izz="0.154779" ixy="1e-06" iyz="0.0" ixz="0.00047"/>
  </inertial>
  <visual>
    <origin xyz="0 0 0" rpy="0 0 0"/>
    <geometry>
      <mesh filename="package://uvc_robot_description/meshes/base_link.stl" scale="0.001 0.001 0.001"/>
    </geometry>
    <material name="silver"/>
  </visual>
  <collision>
    <origin xyz="0 0 0" rpy="0 0 0"/>
    <geometry>
      <mesh filename="package://uvc_robot_description/meshes/base_link.stl" scale="0.001 0.001 0.001"/>
    </geometry>
  </collision>
</link>

<link name="Wheel_1">
  <inertial>
    <origin xyz="-1.2526579066529653e-06 -0.007884164770194352 -9.612705091574525e-07" rpy="0 0 0"/>
    <mass value="0.029886631406815363"/>
    <inertia ixx="1.1e-05" iyy="2.1e-05" izz="1.1e-05" ixy="-0.0" iyz="0.0" ixz="0.0"/>
  </inertial>
  <visual>
    <origin xyz="0.0835 0.199 -0.033" rpy="0 0 0"/>
    <geometry>
      <mesh filename="package://uvc_robot_description/meshes/Wheel_1.stl" scale="0.001 0.001 0.001"/>
    </geometry>
    <material name="silver"/>
  </visual>
  <collision>
    <origin xyz="0.0835 0.199 -0.033" rpy="0 0 0"/>
    <geometry>
      <mesh filename="package://uvc_robot_description/meshes/Wheel_1.stl" scale="0.001 0.001 0.001"/>
    </geometry>
  </collision>
</link>

<link name="Wheel_2">
  <inertial>
    <origin xyz="-1.321639445578393e-06 0.007884164770174229 8.653233252858827e-07" rpy="0 0 0"/>
    <mass value="0.029886631406815363"/>
    <inertia ixx="1.1e-05" iyy="2.1e-05" izz="1.1e-05" ixy="0.0" iyz="0.0" ixz="-0.0"/>
  </inertial>
  <visual>
    <origin xyz="0.0835 -0.199 -0.033" rpy="0 0 0"/>
    <geometry>
      <mesh filename="package://uvc_robot_description/meshes/Wheel_2.stl" scale="0.001 0.001 0.001"/>
    </geometry>
    <material name="silver"/>
  </visual>
  <collision>
    <origin xyz="0.0835 -0.199 -0.033" rpy="0 0 0"/>
    <geometry>
      <mesh filename="package://uvc_robot_description/meshes/Wheel_2.stl" scale="0.001 0.001 0.001"/>
    </geometry>
  </collision>
</link>

<link name="Servo_1">
  <inertial>
    <origin xyz="0.007751503260422843 -0.006785641524481634 -0.014249999999995495" rpy="0 0 0"/>
    <mass value="0.3417439075057314"/>
    <inertia ixx="5.5e-05" iyy="8.4e-05" izz="9.5e-05" ixy="-1e-06" iyz="0.0" ixz="0.0"/>
  </inertial>
  <visual>
    <origin xyz="0.0795 0.174 -0.04725" rpy="0 0 0"/>
    <geometry>
      <mesh filename="package://uvc_robot_description/meshes/Servo_1.stl" scale="0.001 0.001 0.001"/>
    </geometry>
    <material name="silver"/>
  </visual>
  <collision>
    <origin xyz="0.0795 0.174 -0.04725" rpy="0 0 0"/>
    <geometry>
      <mesh filename="package://uvc_robot_description/meshes/Servo_1.stl" scale="0.001 0.001 0.001"/>
    </geometry>
  </collision>
</link>

<link name="Servo_3">
  <inertial>
    <origin xyz="0.0077515032604229955 -0.0052143584755384165 -0.014250000000024472" rpy="0 0 0"/>
    <mass value="0.3417439075057314"/>
    <inertia ixx="5.5e-05" iyy="8.4e-05" izz="9.5e-05" ixy="1e-06" iyz="0.0" ixz="-0.0"/>
  </inertial>
  <visual>
    <origin xyz="0.0795 -0.186 -0.04725" rpy="0 0 0"/>
    <geometry>
      <mesh filename="package://uvc_robot_description/meshes/Servo_3.stl" scale="0.001 0.001 0.001"/>
    </geometry>
    <material name="silver"/>
  </visual>
  <collision>
    <origin xyz="0.0795 -0.186 -0.04725" rpy="0 0 0"/>
    <geometry>
      <mesh filename="package://uvc_robot_description/meshes/Servo_3.stl" scale="0.001 0.001 0.001"/>
    </geometry>
  </collision>
</link>

<link name="Layer_1">
  <inertial>
    <origin xyz="0.16056846638009492 -0.023998313855767887 0.09462855003732062" rpy="0 0 0"/>
    <mass value="5.453505423835813"/>
    <inertia ixx="0.066842" iyy="0.046567" izz="0.113336" ixy="-0.0" iyz="-0.0" ixz="8.3e-05"/>
  </inertial>
  <visual>
    <origin xyz="0.1475 -0.024 -0.1005" rpy="0 0 0"/>
    <geometry>
      <mesh filename="package://uvc_robot_description/meshes/Layer_1.stl" scale="0.001 0.001 0.001"/>
    </geometry>
    <material name="silver"/>
  </visual>
  <collision>
    <origin xyz="0.1475 -0.024 -0.1005" rpy="0 0 0"/>
    <geometry>
      <mesh filename="package://uvc_robot_description/meshes/Layer_1.stl" scale="0.001 0.001 0.001"/>
    </geometry>
  </collision>
</link>

<link name="batteries_1">
  <inertial>
    <origin xyz="3.55964825843477e-17 -7.696536774994098e-17 0.03478104967731738" rpy="0 0 0"/>
    <mass value="9.23198"/>
    <inertia ixx="0.08807" iyy="0.077039" izz="0.151495" ixy="0.0" iyz="-0.0" ixz="-0.0"/>
  </inertial>
  <visual>
    <origin xyz="0.0 0.0 -0.1005" rpy="0 0 0"/>
    <geometry>
      <mesh filename="package://uvc_robot_description/meshes/batteries_1.stl" scale="0.001 0.001 0.001"/>
    </geometry>
    <material name="silver"/>
  </visual>
  <collision>
    <origin xyz="0.0 0.0 -0.1005" rpy="0 0 0"/>
    <geometry>
      <mesh filename="package://uvc_robot_description/meshes/batteries_1.stl" scale="0.001 0.001 0.001"/>
    </geometry>
  </collision>
</link>

<link name="UVC_device_1">
  <inertial>
    <origin xyz="-0.0849315906364422 -0.0344999999999998 0.07895099801487448" rpy="0 0 0"/>
    <mass value="59.045511211776116"/>
    <inertia ixx="1.10083" iyy="0.21065" izz="1.100894" ixy="-0.0" iyz="0.0" ixz="0.05585"/>
  </inertial>
  <visual>
    <origin xyz="0.167274 -0.0345 -0.05325" rpy="0 0 0"/>
    <geometry>
      <mesh filename="package://uvc_robot_description/meshes/UVC_device_1.stl" scale="0.001 0.001 0.001"/>
    </geometry>
    <material name="silver"/>
  </visual>
  <collision>
    <origin xyz="0.167274 -0.0345 -0.05325" rpy="0 0 0"/>
    <geometry>
      <mesh filename="package://uvc_robot_description/meshes/UVC_device_1.stl" scale="0.001 0.001 0.001"/>
    </geometry>
  </collision>
</link>

<link name="D435i_holder_1">
  <inertial>
    <origin xyz="-0.0004455067937094159 0.011000045594827305 0.008510026036720603" rpy="0 0 0"/>
    <mass value="0.042723847582990575"/>
    <inertia ixx="1.2e-05" iyy="1e-06" izz="1.1e-05" ixy="-0.0" iyz="-0.0" ixz="0.0"/>
  </inertial>
  <visual>
    <origin xyz="0.1155 0.011 -0.19975" rpy="0 0 0"/>
    <geometry>
      <mesh filename="package://uvc_robot_description/meshes/D435i_holder_1.stl" scale="0.001 0.001 0.001"/>
    </geometry>
    <material name="silver"/>
  </visual>
  <collision>
    <origin xyz="0.1155 0.011 -0.19975" rpy="0 0 0"/>
    <geometry>
      <mesh filename="package://uvc_robot_description/meshes/D435i_holder_1.stl" scale="0.001 0.001 0.001"/>
    </geometry>
  </collision>
</link>

<link name="LDS_01_1">
  <inertial>
    <origin xyz="0.04110282018212476 1.2852748238388835e-05 0.0006058198119665015" rpy="0 0 0"/>
    <mass value="0.05487799206614008"/>
    <inertia ixx="1.8e-05" iyy="3.6e-05" izz="4.5e-05" ixy="0.0" iyz="-0.0" ixz="5e-06"/>
  </inertial>
  <visual>
    <origin xyz="0.112923 -0.0 -0.216824" rpy="0 0 0"/>
    <geometry>
      <mesh filename="package://uvc_robot_description/meshes/LDS_01_1.stl" scale="0.001 0.001 0.001"/>
    </geometry>
    <material name="silver"/>
  </visual>
  <collision>
    <origin xyz="0.112923 -0.0 -0.216824" rpy="0 0 0"/>
    <geometry>
      <mesh filename="package://uvc_robot_description/meshes/LDS_01_1.stl" scale="0.001 0.001 0.001"/>
    </geometry>
  </collision>
</link>

<link name="D435_1">
  <inertial>
    <origin xyz="-0.0009785662386554983 -1.1079651969674652e-05 0.012138125786803927" rpy="0 0 0"/>
    <mass value="0.10791100846631752"/>
    <inertia ixx="7.1e-05" iyy="1e-05" izz="7.2e-05" ixy="-0.0" iyz="0.0" ixz="-0.0"/>
  </inertial>
  <visual>
    <origin xyz="0.1295 0.0 -0.19975" rpy="0 0 0"/>
    <geometry>
      <mesh filename="package://uvc_robot_description/meshes/D435_1.stl" scale="0.001 0.001 0.001"/>
    </geometry>
    <material name="silver"/>
  </visual>
  <collision>
    <origin xyz="0.1295 0.0 -0.19975" rpy="0 0 0"/>
    <geometry>
      <mesh filename="package://uvc_robot_description/meshes/D435_1.stl" scale="0.001 0.001 0.001"/>
    </geometry>
  </collision>
</link>

<joint name="Revolute 1" type="continuous">
  <origin xyz="-0.004 -0.025 -0.01425" rpy="0 0 0"/>
  <parent link="Servo_1"/>
  <child link="Wheel_1"/>
  <axis xyz="0.0 1.0 0.0"/>
</joint>

<joint name="Revolute 2" type="continuous">
  <origin xyz="-0.004 0.013 -0.01425" rpy="0 0 0"/>
  <parent link="Servo_3"/>
  <child link="Wheel_2"/>
  <axis xyz="-0.0 -1.0 0.0"/>
</joint>

<joint name="Rigid 3" type="fixed">
  <origin xyz="-0.0795 -0.174 0.04725" rpy="0 0 0"/>
  <parent link="base_link"/>
  <child link="Servo_1"/>
</joint>

<joint name="Rigid 4" type="fixed">
  <origin xyz="-0.0795 0.186 0.04725" rpy="0 0 0"/>
  <parent link="base_link"/>
  <child link="Servo_3"/>
</joint>

<joint name="Rigid 5" type="fixed">
  <origin xyz="-0.1475 0.024 0.1005" rpy="0 0 0"/>
  <parent link="base_link"/>
  <child link="Layer_1"/>
</joint>

<joint name="Rigid 6" type="fixed">
  <origin xyz="0.0 0.0 0.1005" rpy="0 0 0"/>
  <parent link="base_link"/>
  <child link="batteries_1"/>
</joint>

<joint name="Rigid 7" type="fixed">
  <origin xyz="-0.167274 0.0345 0.05325" rpy="0 0 0"/>
  <parent link="base_link"/>
  <child link="UVC_device_1"/>
</joint>

<joint name="Rigid 8" type="fixed">
  <origin xyz="0.032 -0.035 0.09925" rpy="0 0 0"/>
  <parent link="Layer_1"/>
  <child link="D435i_holder_1"/>
</joint>

<joint name="Rigid 9" type="fixed">
  <origin xyz="0.002577 0.011 0.017074" rpy="0 0 0"/>
  <parent link="D435i_holder_1"/>
  <child link="LDS_01_1"/>
</joint>

<joint name="Rigid 10" type="fixed">
  <origin xyz="0.018 -0.024 0.09925" rpy="0 0 0"/>
  <parent link="Layer_1"/>
  <child link="D435_1"/>
</joint>

</robot>
